Workbook

Sheet Raw_Transactions
A1: Transaction_ID | B1: Customer_ID | C1: Date | D1: Amount | E1: Channel | F1: Country | G1: Merchant_Category
A2: TXN_000001 | B2: C_00169 | C2: 2026-01-01 | D2: 20787.1 | E2: Card | F2: US | G2: Electronics
A3: TXN_001730 | B3: C_00169 | C3: 2026-01-01 | D3: 20787.1 | E3: Card | F3: US | G3: Electronics
A4: TXN_000012 | B4: C_00199 | C4: 2026-01-01 | D4: 249.11 | E4: ACH | F4: US | G4: Retail
A5: TXN_000011 | B5: C_00051 | C5: 2026-01-01 | D5: 2437.78 | E5: Mobile App | F5: US | G5: Money Services
A6: TXN_000009 | B6: C_00195 | C6: 2026-01-01 | D6: 499.42 | E6: Card | F6: US | G6: Food & Beverage
A7: TXN_000008 | B7: C_00296 | C7: 2026-01-01 | D7: 2796.56 | E7: Card | F7: CA | G7: Money Services
A8: TXN_000010 | B8: C_00247 | C8: 2026-01-01 | D8: 661.85 | E8: Cash Deposit | F8: US | G8: Crypto Exchange
A9: TXN_000006 | B9: C_00060 | C9: 2026-01-01 | D9: 1666.4 | E9: Cash Deposit | F9: MX | G9: Travel
A10: TXN_000005 | B10: C_00093 | C10: 2026-01-01 | D10: 825.92 | E10: Wire Transfer | F10: RU | G10: Jewelry
A11: TXN_000004 | B11: C_00197 | C11: 2026-01-01 | D11: 721.52 | E11: Card | F11: US | G11: Real Estate
A12: TXN_000003 | B12: C_00258 | C12: 2026-01-01 | D12: 622.31 | E12: Cash Deposit | F12: US | G12: Real Estate
A13: TXN_000002 | B13: C_00106 | C13: 2026-01-01 | D13: 523.89 | E13: Cash Deposit | F13: US | G13: Real Estate
... A1735: TXN_001614 | B1735: C_00160 | C1735: 2026-04-30 | D1735: 565.18 | E1735: ACH | F1735: US | G1735: Electronics

Sheet Raw_Risk_Profiles
A1: Customer_ID | B1: Risk_Rating | C1: KYC_Status | D1: Account_Age_Months | E1: Customer_Segment
A2: C_00001 | B2: High | C2: Complete | D2: 16 | E2: HNI
A3: C_00002 | B3: High | C3: Complete | D3: 94 | E3: HNI
A4: C_00003 | B4: High | C4: Complete | D4: 80 | E4: HNI
A5: C_00004 | B5: High | C5: Complete | D5: 56 | E5: HNI
A6: C_00005 | B6: High | C6: Complete | D6: 55 | E6: HNI
A7: C_00006 | B7: High | C7: Complete | D7: 103 | E7: HNI
A8: C_00007 | B8: High | C8: Complete | D8: 15 | E8: HNI
A9: C_00008 | B9: High | C9: Complete | D9: 85 | E9: HNI
A10: C_00009 | B10: High | C10: Complete | D10: 28 | E10: HNI
A11: C_00010 | B11: High | C11: Complete | D11: 16 | E11: HNI
A12: C_00011 | B12: High | C12: Complete | D12: 66 | E12: HNI
A13: C_00012 | B13: High | C13: Complete | D13: 117 | E13: HNI
... A301: C_00300 | B301: Medium | C301: Complete | D301: 67 | E301: Corporate

Sheet Raw_Alerts
A1: Alert_ID | B1: Transaction_ID | C1: Alert_Type | D1: Alert_Date | E1: Status | F1: Resolution_Time_Days
A2: ALT_00001 | B2: TXN_001727 | C2: Structuring | D2: 2026-02-10 | E2: Closed | F2: 1
A3: ALT_00002 | B3: TXN_001701 | C3: Structuring | D3: 2026-02-10 | E3: Closed | F3: 2
A4: ALT_00003 | B4: TXN_001719 | C4: Structuring | D4: 2026-02-10 | E4: Closed | F4: 2
A5: ALT_00004 | B5: TXN_001717 | C5: Structuring | D5: 2026-02-10 | E5: Closed | F5: 1
A6: ALT_00005 | B6: TXN_001715 | C6: Structuring | D6: 2026-02-10 | E6: Closed | F6: 2
A7: ALT_00006 | B7: TXN_001710 | C7: Structuring | D7: 2026-02-10 | E7: Closed | F7: 2
A8: ALT_00007 | B8: TXN_001708 | C8: Structuring | D8: 2026-02-10 | E8: Open
A9: ALT_00008 | B9: TXN_001698 | C9: Structuring | D9: 2026-02-10 | E9: Closed | F9: 2
A10: ALT_00009 | B10: TXN_001684 | C10: Structuring | D10: 2026-02-10 | E10: Open
A11: ALT_00010 | B11: TXN_001693 | C11: Structuring | D11: 2026-02-10 | E11: Closed | F11: 3
A12: ALT_00011 | B12: TXN_001686 | C12: Structuring | D12: 2026-02-10 | E12: Closed | F12: 3
A13: ALT_00012 | B13: TXN_001679 | C13: Structuring | D13: 2026-02-10 | E13: Open
A14: ALT_00013 | B14: TXN_001678 | C14: Structuring | D14: 2026-02-10 | E14: Open
A15: ALT_00014 | B15: TXN_001729 | C15: Structuring | D15: 2026-02-10 | E15: Closed | F15: 1
A16: ALT_00015 | B16: TXN_001672 | C16: Structuring | D16: 2026-02-10 | E16: Closed | F16: 2
A17: ALT_00016 | B17: TXN_001670 | C17: Structuring | D17: 2026-02-10 | E17: Closed | F17: 3
A18: ALT_00017 | B18: TXN_001667 | C18: Structuring | D18: 2026-02-10 | E18: Open
A19: ALT_00018 | B19: TXN_001665 | C19: Structuring | D19: 2026-02-10 | E19: Closed | F19: 1
A20: ALT_00019 | B20: TXN_001663 | C20: Structuring | D20: 2026-02-10 | E20: Closed | F20: 2
A21: ALT_00020 | B21: TXN_001662 | C21: Structuring | D21: 2026-02-10 | E21: Closed | F21: 1
A22: ALT_00021 | B22: TXN_001641 | C22: Structuring | D22: 2026-02-10 | E22: Closed | F22: 1
A23: ALT_00022 | B23: TXN_001697 | C23: Structuring | D23: 2026-02-10 | E23: Open
A24: ALT_00023 | B24: TXN_001676 | C24: Structuring | D24: 2026-02-10 | E24: Closed | F24: 1
A25: ALT_00024 | B25: TXN_001721 | C25: Structuring | D25: 2026-02-10 | E25: Open
A26: ALT_00025 | B26: TXN_001632 | C26: Structuring | D26: 2026-02-10 | E26: Open
A27: ALT_00026 | B27: TXN_001691 | C27: Structuring | D27: 2026-02-11 | E27: Open
A28: ALT_00027 | B28: TXN_001633 | C28: Structuring | D28: 2026-02-11 | E28: Closed | F28: 1
A29: ALT_00028 | B29: TXN_001683 | C29: Structuring | D29: 2026-02-11 | E29: Closed | F29: 1
A30: ALT_00029 | B30: TXN_001680 | C30: Structuring | D30: 2026-02-11 | E30: Closed | F30: 2
A31: ALT_00030 | B31: TXN_001646 | C31: Structuring | D31: 2026-02-11 | E31: Closed | F31: 3
A32: ALT_00031 | B32: TXN_001702 | C32: Structuring | D32: 2026-02-11 | E32: Open
A33: ALT_00032 | B33: TXN_001654 | C33: Structuring | D33: 2026-02-11 | E33: Closed | F33: 2
A34: ALT_00033 | B34: TXN_001656 | C34: Structuring | D34: 2026-02-11 | E34: Closed | F34: 1
A35: ALT_00034 | B35: TXN_001681 | C35: Structuring | D35: 2026-02-11 | E35: Open
A36: ALT_00035 | B36: TXN_001685 | C36: Structuring | D36: 2026-02-11 | E36: Open
A37: ALT_00036 | B37: TXN_001638 | C37: Structuring | D37: 2026-02-12 | E37: Closed | F37: 3
A38: ALT_00037 | B38: TXN_001642 | C38: Structuring | D38: 2026-02-12 | E38: Closed | F38: 3
A39: ALT_00038 | B39: TXN_001649 | C39: Structuring | D39: 2026-02-12 | E39: Open
A40: ALT_00039 | B40: TXN_001650 | C40: Structuring | D40: 2026-02-12 | E40: Closed | F40: 2
...

Sheet Consolidated_View
A1: Transaction_ID | B1: Customer_ID | C1: Date | D1: Amount | E1: Channel | F1: Country | G1: Merchant_Category | H1: Risk_Rating | I1: KYC_Status | J1: Account_Age_Months | K1: Customer_Segment | L1: Alert_ID | M1: Alert_Type | N1: Alert_Date | O1: Resolution_Days | P1: Data_Quality_Flag
A2: =Raw_Transactions!A2 | B2: =Raw_Transactions!B2 | C2: =Raw_Transactions!C2 | D2: =Raw_Transactions!D2 | E2: =Raw_Transactions!E2 | F2: =Raw_Transactions!F2 | G2: =Raw_Transactions!G2 | H2: =XLOOKUP(B2,Raw_Risk_Profiles!$A:$A,Raw_Risk_Profiles!$B:$B,"Not Found") | I2: =XLOOKUP(B2,Raw_Risk_Profiles!$A:$A,Raw_Risk_Profiles!$C:$C,"Missing") | J2: =XLOOKUP(B2,Raw_Risk_Profiles!$A:$A,Raw_Risk_Profiles!$D:$D,"") | K2: =IFERROR(INDEX(Raw_Risk_Profiles!$E:$E,MATCH(B2,Raw_Risk_Profiles!$A:$A,0)),"Unknown") | L2: =IFERROR(XLOOKUP(A2,Raw_Alerts!$B:$B,Raw_Alerts!$A:$A),"No Alert") | M2: =IFERROR(XLOOKUP(A2,Raw_Alerts!$B:$B,Raw_Alerts!$C:$C),"") | N2: =IFERROR(XLOOKUP(A2,Raw_Alerts!$B:$B,Raw_Alerts!$D:$D),"") | O2: =IFERROR(XLOOKUP(A2,Raw_Alerts!$B:$B,Raw_Alerts!$F:$F),"") | P2: =IF(H2="Not Found","CRITICAL: No Risk Profile",IF(I2="Missing","WARN: Missing KYC",IF(I2="Expired","WARN: KYC Expired",IF(I2="Pending","INFO: KYC Pending","OK"))))
A3: =Raw_Transactions!A3 | B3: =Raw_Transactions!B3 | C3: =Raw_Transactions!C3 | D3: =Raw_Transactions!D3 | E3: =Raw_Transactions!E3 | F3: =Raw_Transactions!F3 | G3: =Raw_Transactions!G3 | H3: =XLOOKUP(B3,Raw_Risk_Profiles!$A:$A,Raw_Risk_Profiles!$B:$B,"Not Found") | I3: =XLOOKUP(B3,Raw_Risk_Profiles!$A:$A,Raw_Risk_Profiles!$C:$C,"Missing") | J3: =XLOOKUP(B3,Raw_Risk_Profiles!$A:$A,Raw_Risk_Profiles!$D:$D,"") | K3: =IFERROR(INDEX(Raw_Risk_Profiles!$E:$E,MATCH(B3,Raw_Risk_Profiles!$A:$A,0)),"Unknown") | L3: =IFERROR(XLOOKUP(A3,Raw_Alerts!$B:$B,Raw_Alerts!$A:$A),"No Alert") | M3: =IFERROR(XLOOKUP(A3,Raw_Alerts!$B:$B,Raw_Alerts!$C:$C),"") | N3: =IFERROR(XLOOKUP(A3,Raw_Alerts!$B:$B,Raw_Alerts!$D:$D),"") | O3: =IFERROR(XLOOKUP(A3,Raw_Alerts!$B:$B,Raw_Alerts!$F:$F),"") | P3: =IF(H3="Not Found","CRITICAL: No Risk Profile",IF(I3="Missing","WARN: Missing KYC",IF(I3="Expired","WARN: KYC Expired",IF(I3="Pending","INFO: KYC Pending","OK"))))
A4: =Raw_Transactions!A4 | B4: =Raw_Transactions!B4 | C4: =Raw_Transactions!C4 | D4: =Raw_Transactions!D4 | E4: =Raw_Transactions!E4 | F4: =Raw_Transactions!F4 | G4: =Raw_Transactions!G4 | H4: =XLOOKUP(B4,Raw_Risk_Profiles!$A:$A,Raw_Risk_Profiles!$B:$B,"Not Found") | I4: =XLOOKUP(B4,Raw_Risk_Profiles!$A:$A,Raw_Risk_Profiles!$C:$C,"Missing") | J4: =XLOOKUP(B4,Raw_Risk_Profiles!$A:$A,Raw_Risk_Profiles!$D:$D,"") | K4: =IFERROR(INDEX(Raw_Risk_Profiles!$E:$E,MATCH(B4,Raw_Risk_Profiles!$A:$A,0)),"Unknown") | L4: =IFERROR(XLOOKUP(A4,Raw_Alerts!$B:$B,Raw_Alerts!$A:$A),"No Alert") | M4: =IFERROR(XLOOKUP(A4,Raw_Alerts!$B:$B,Raw_Alerts!$C:$C),"") | N4: =IFERROR(XLOOKUP(A4,Raw_Alerts!$B:$B,Raw_Alerts!$D:$D),"") | O4: =IFERROR(XLOOKUP(A4,Raw_Alerts!$B:$B,Raw_Alerts!$F:$F),"") | P4: =IF(H4="Not Found","CRITICAL: No Risk Profile",IF(I4="Missing","WARN: Missing KYC",IF(I4="Expired","WARN: KYC Expired",IF(I4="Pending","INFO: KYC Pending","OK"))))
A5: =Raw_Transactions!A5 | B5: =Raw_Transactions!B5 | C5: =Raw_Transactions!C5 | D5: =Raw_Transactions!D5 | E5: =Raw_Transactions!E5 | F5: =Raw_Transactions!F5 | G5: =Raw_Transactions!G5 | H5: =XLOOKUP(B5,Raw_Risk_Profiles!$A:$A,Raw_Risk_Profiles!$B:$B,"Not Found") | I5: =XLOOKUP(B5,Raw_Risk_Profiles!$A:$A,Raw_Risk_Profiles!$C:$C,"Missing") | J5: =XLOOKUP(B5,Raw_Risk_Profiles!$A:$A,Raw_Risk_Profiles!$D:$D,"") | K5: =IFERROR(INDEX(Raw_Risk_Profiles!$E:$E,MATCH(B5,Raw_Risk_Profiles!$A:$A,0)),"Unknown") | L5: =IFERROR(XLOOKUP(A5,Raw_Alerts!$B:$B,Raw_Alerts!$A:$A),"No Alert") | M5: =IFERROR(XLOOKUP(A5,Raw_Alerts!$B:$B,Raw_Alerts!$C:$C),"") | N5: =IFERROR(XLOOKUP(A5,Raw_Alerts!$B:$B,Raw_Alerts!$D:$D),"") | O5: =IFERROR(XLOOKUP(A5,Raw_Alerts!$B:$B,Raw_Alerts!$F:$F),"") | P5: =IF(H5="Not Found","CRITICAL: No Risk Profile",IF(I5="Missing","WARN: Missing KYC",IF(I5="Expired","WARN: KYC Expired",IF(I5="Pending","INFO: KYC Pending","OK"))))
A6: =Raw_Transactions!A6 | B6: =Raw_Transactions!B6 | C6: =Raw_Transactions!C6 | D6: =Raw_Transactions!D6 | E6: =Raw_Transactions!E6 | F6: =Raw_Transactions!F6 | G6: =Raw_Transactions!G6 | H6: =XLOOKUP(B6,Raw_Risk_Profiles!$A:$A,Raw_Risk_Profiles!$B:$B,"Not Found") | I6: =XLOOKUP(B6,Raw_Risk_Profiles!$A:$A,Raw_Risk_Profiles!$C:$C,"Missing") | J6: =XLOOKUP(B6,Raw_Risk_Profiles!$A:$A,Raw_Risk_Profiles!$D:$D,"") | K6: =IFERROR(INDEX(Raw_Risk_Profiles!$E:$E,MATCH(B6,Raw_Risk_Profiles!$A:$A,0)),"Unknown") | L6: =IFERROR(XLOOKUP(A6,Raw_Alerts!$B:$B,Raw_Alerts!$A:$A),"No Alert") | M6: =IFERROR(XLOOKUP(A6,Raw_Alerts!$B:$B,Raw_Alerts!$C:$C),"") | N6: =IFERROR(XLOOKUP(A6,Raw_Alerts!$B:$B,Raw_Alerts!$D:$D),"") | O6: =IFERROR(XLOOKUP(A6,Raw_Alerts!$B:$B,Raw_Alerts!$F:$F),"") | P6: =IF(H6="Not Found","CRITICAL: No Risk Profile",IF(I6="Missing","WARN: Missing KYC",IF(I6="Expired","WARN: KYC Expired",IF(I6="Pending","INFO: KYC Pending","OK"))))
A7: =Raw_Transactions!A7 | B7: =Raw_Transactions!B7 | C7: =Raw_Transactions!C7 | D7: =Raw_Transactions!D7 | E7: =Raw_Transactions!E7 | F7: =Raw_Transactions!F7 | G7: =Raw_Transactions!G7 | H7: =XLOOKUP(B7,Raw_Risk_Profiles!$A:$A,Raw_Risk_Profiles!$B:$B,"Not Found") | I7: =XLOOKUP(B7,Raw_Risk_Profiles!$A:$A,Raw_Risk_Profiles!$C:$C,"Missing") | J7: =XLOOKUP(B7,Raw_Risk_Profiles!$A:$A,Raw_Risk_Profiles!$D:$D,"") | K7: =IFERROR(INDEX(Raw_Risk_Profiles!$E:$E,MATCH(B7,Raw_Risk_Profiles!$A:$A,0)),"Unknown") | L7: =IFERROR(XLOOKUP(A7,Raw_Alerts!$B:$B,Raw_Alerts!$A:$A),"No Alert") | M7: =IFERROR(XLOOKUP(A7,Raw_Alerts!$B:$B,Raw_Alerts!$C:$C),"") | N7: =IFERROR(XLOOKUP(A7,Raw_Alerts!$B:$B,Raw_Alerts!$D:$D),"") | O7: =IFERROR(XLOOKUP(A7,Raw_Alerts!$B:$B,Raw_Alerts!$F:$F),"") | P7: =IF(H7="Not Found","CRITICAL: No Risk Profile",IF(I7="Missing","WARN: Missing KYC",IF(I7="Expired","WARN: KYC Expired",IF(I7="Pending","INFO: KYC Pending","OK"))))
A8: =Raw_Transactions!A8 | B8: =Raw_Transactions!B8 | C8: =Raw_Transactions!C8 | D8: =Raw_Transactions!D8 | E8: =Raw_Transactions!E8 | F8: =Raw_Transactions!F8 | G8: =Raw_Transactions!G8 | H8: =XLOOKUP(B8,Raw_Risk_Profiles!$A:$A,Raw_Risk_Profiles!$B:$B,"Not Found") | I8: =XLOOKUP(B8,Raw_Risk_Profiles!$A:$A,Raw_Risk_Profiles!$C:$C,"Missing") | J8: =XLOOKUP(B8,Raw_Risk_Profiles!$A:$A,Raw_Risk_Profiles!$D:$D,"") | K8: =IFERROR(INDEX(Raw_Risk_Profiles!$E:$E,MATCH(B8,Raw_Risk_Profiles!$A:$A,0)),"Unknown") | L8: =IFERROR(XLOOKUP(A8,Raw_Alerts!$B:$B,Raw_Alerts!$A:$A),"No Alert") | M8: =IFERROR(XLOOKUP(A8,Raw_Alerts!$B:$B,Raw_Alerts!$C:$C),"") | N8: =IFERROR(XLOOKUP(A8,Raw_Alerts!$B:$B,Raw_Alerts!$D:$D),"") | O8: =IFERROR(XLOOKUP(A8,Raw_Alerts!$B:$B,Raw_Alerts!$F:$F),"") | P8: =IF(H8="Not Found","CRITICAL: No Risk Profile",IF(I8="Missing","WARN: Missing KYC",IF(I8="Expired","WARN: KYC Expired",IF(I8="Pending","INFO: KYC Pending","OK"))))
A9: =Raw_Transactions!A9 | B9: =Raw_Transactions!B9 | C9: =Raw_Transactions!C9 | D9: =Raw_Transactions!D9 | E9: =Raw_Transactions!E9 | F9: =Raw_Transactions!F9 | G9: =Raw_Transactions!G9 | H9: =XLOOKUP(B9,Raw_Risk_Profiles!$A:$A,Raw_Risk_Profiles!$B:$B,"Not Found") | I9: =XLOOKUP(B9,Raw_Risk_Profiles!$A:$A,Raw_Risk_Profiles!$C:$C,"Missing") | J9: =XLOOKUP(B9,Raw_Risk_Profiles!$A:$A,Raw_Risk_Profiles!$D:$D,"") | K9: =IFERROR(INDEX(Raw_Risk_Profiles!$E:$E,MATCH(B9,Raw_Risk_Profiles!$A:$A,0)),"Unknown") | L9: =IFERROR(XLOOKUP(A9,Raw_Alerts!$B:$B,Raw_Alerts!$A:$A),"No Alert") | M9: =IFERROR(XLOOKUP(A9,Raw_Alerts!$B:$B,Raw_Alerts!$C:$C),"") | N9: =IFERROR(XLOOKUP(A9,Raw_Alerts!$B:$B,Raw_Alerts!$D:$D),"") | O9: =IFERROR(XLOOKUP(A9,Raw_Alerts!$B:$B,Raw_Alerts!$F:$F),"") | P9: =IF(H9="Not Found","CRITICAL: No Risk Profile",IF(I9="Missing","WARN: Missing KYC",IF(I9="Expired","WARN: KYC Expired",IF(I9="Pending","INFO: KYC Pending","OK"))))
A10: =Raw_Transactions!A10 | B10: =Raw_Transactions!B10 | C10: =Raw_Transactions!C10 | D10: =Raw_Transactions!D10 | E10: =Raw_Transactions!E10 | F10: =Raw_Transactions!F10 | G10: =Raw_Transactions!G10 | H10: =XLOOKUP(B10,Raw_Risk_Profiles!$A:$A,Raw_Risk_Profiles!$B:$B,"Not Found") | I10: =XLOOKUP(B10,Raw_Risk_Profiles!$A:$A,Raw_Risk_Profiles!$C:$C,"Missing") | J10: =XLOOKUP(B10,Raw_Risk_Profiles!$A:$A,Raw_Risk_Profiles!$D:$D,"") | K10: =IFERROR(INDEX(Raw_Risk_Profiles!$E:$E,MATCH(B10,Raw_Risk_Profiles!$A:$A,0)),"Unknown") | L10: =IFERROR(XLOOKUP(A10,Raw_Alerts!$B:$B,Raw_Alerts!$A:$A),"No Alert") | M10: =IFERROR(XLOOKUP(A10,Raw_Alerts!$B:$B,Raw_Alerts!$C:$C),"") | N10: =IFERROR(XLOOKUP(A10,Raw_Alerts!$B:$B,Raw_Alerts!$D:$D),"") | O10: =IFERROR(XLOOKUP(A10,Raw_Alerts!$B:$B,Raw_Alerts!$F:$F),"") | P10: =IF(H10="Not Found","CRITICAL: No Risk Profile",IF(I10="Missing","WARN: Missing KYC",IF(I10="Expired","WARN: KYC Expired",IF(I10="Pending","INFO: KYC Pending","OK"))))
A11: =Raw_Transactions!A11 | B11: =Raw_Transactions!B11 | C11: =Raw_Transactions!C11 | D11: =Raw_Transactions!D11 | E11: =Raw_Transactions!E11 | F11: =Raw_Transactions!F11 | G11: =Raw_Transactions!G11 | H11: =XLOOKUP(B11,Raw_Risk_Profiles!$A:$A,Raw_Risk_Profiles!$B:$B,"Not Found") | I11: =XLOOKUP(B11,Raw_Risk_Profiles!$A:$A,Raw_Risk_Profiles!$C:$C,"Missing") | J11: =XLOOKUP(B11,Raw_Risk_Profiles!$A:$A,Raw_Risk_Profiles!$D:$D,"") | K11: =IFERROR(INDEX(Raw_Risk_Profiles!$E:$E,MATCH(B11,Raw_Risk_Profiles!$A:$A,0)),"Unknown") | L11: =IFERROR(XLOOKUP(A11,Raw_Alerts!$B:$B,Raw_Alerts!$A:$A),"No Alert") | M11: =IFERROR(XLOOKUP(A11,Raw_Alerts!$B:$B,Raw_Alerts!$C:$C),"") | N11: =IFERROR(XLOOKUP(A11,Raw_Alerts!$B:$B,Raw_Alerts!$D:$D),"") | O11: =IFERROR(XLOOKUP(A11,Raw_Alerts!$B:$B,Raw_Alerts!$F:$F),"") | P11: =IF(H11="Not Found","CRITICAL: No Risk Profile",IF(I11="Missing","WARN: Missing KYC",IF(I11="Expired","WARN: KYC Expired",IF(I11="Pending","INFO: KYC Pending","OK"))))
A12: =Raw_Transactions!A12 | B12: =Raw_Transactions!B12 | C12: =Raw_Transactions!C12 | D12: =Raw_Transactions!D12 | E12: =Raw_Transactions!E12 | F12: =Raw_Transactions!F12 | G12: =Raw_Transactions!G12 | H12: =XLOOKUP(B12,Raw_Risk_Profiles!$A:$A,Raw_Risk_Profiles!$B:$B,"Not Found") | I12: =XLOOKUP(B12,Raw_Risk_Profiles!$A:$A,Raw_Risk_Profiles!$C:$C,"Missing") | J12: =XLOOKUP(B12,Raw_Risk_Profiles!$A:$A,Raw_Risk_Profiles!$D:$D,"") | K12: =IFERROR(INDEX(Raw_Risk_Profiles!$E:$E,MATCH(B12,Raw_Risk_Profiles!$A:$A,0)),"Unknown") | L12: =IFERROR(XLOOKUP(A12,Raw_Alerts!$B:$B,Raw_Alerts!$A:$A),"No Alert") | M12: =IFERROR(XLOOKUP(A12,Raw_Alerts!$B:$B,Raw_Alerts!$C:$C),"") | N12: =IFERROR(XLOOKUP(A12,Raw_Alerts!$B:$B,Raw_Alerts!$D:$D),"") | O12: =IFERROR(XLOOKUP(A12,Raw_Alerts!$B:$B,Raw_Alerts!$F:$F),"") | P12: =IF(H12="Not Found","CRITICAL: No Risk Profile",IF(I12="Missing","WARN: Missing KYC",IF(I12="Expired","WARN: KYC Expired",IF(I12="Pending","INFO: KYC Pending","OK"))))
A13: =Raw_Transactions!A13 | B13: =Raw_Transactions!B13 | C13: =Raw_Transactions!C13 | D13: =Raw_Transactions!D13 | E13: =Raw_Transactions!E13 | F13: =Raw_Transactions!F13 | G13: =Raw_Transactions!G13 | H13: =XLOOKUP(B13,Raw_Risk_Profiles!$A:$A,Raw_Risk_Profiles!$B:$B,"Not Found") | I13: =XLOOKUP(B13,Raw_Risk_Profiles!$A:$A,Raw_Risk_Profiles!$C:$C,"Missing") | J13: =XLOOKUP(B13,Raw_Risk_Profiles!$A:$A,Raw_Risk_Profiles!$D:$D,"") | K13: =IFERROR(INDEX(Raw_Risk_Profiles!$E:$E,MATCH(B13,Raw_Risk_Profiles!$A:$A,0)),"Unknown") | L13: =IFERROR(XLOOKUP(A13,Raw_Alerts!$B:$B,Raw_Alerts!$A:$A),"No Alert") | M13: =IFERROR(XLOOKUP(A13,Raw_Alerts!$B:$B,Raw_Alerts!$C:$C),"") | N13: =IFERROR(XLOOKUP(A13,Raw_Alerts!$B:$B,Raw_Alerts!$D:$D),"") | O13: =IFERROR(XLOOKUP(A13,Raw_Alerts!$B:$B,Raw_Alerts!$F:$F),"") | P13: =IF(H13="Not Found","CRITICAL: No Risk Profile",IF(I13="Missing","WARN: Missing KYC",IF(I13="Expired","WARN: KYC Expired",IF(I13="Pending","INFO: KYC Pending","OK"))))
... A1735: =Raw_Transactions!A1735 | B1735: =Raw_Transactions!B1735 | C1735: =Raw_Transactions!C1735 | D1735: =Raw_Transactions!D1735 | E1735: =Raw_Transactions!E1735 | F1735: =Raw_Transactions!F1735 | G1735: =Raw_Transactions!G1735 | H1735: =XLOOKUP(B1735,Raw_Risk_Profiles!$A:$A,Raw_Risk_Profiles!$B:$B,"Not Found") | I1735: =XLOOKUP(B1735,Raw_Risk_Profiles!$A:$A,Raw_Risk_Profiles!$C:$C,"Missing") | J1735: =XLOOKUP(B1735,Raw_Risk_Profiles!$A:$A,Raw_Risk_Profiles!$D:$D,"") | K1735: =IFERROR(INDEX(Raw_Risk_Profiles!$E:$E,MATCH(B1735,Raw_Risk_Profiles!$A:$A,0)),"Unknown") | L1735: =IFERROR(XLOOKUP(A1735,Raw_Alerts!$B:$B,Raw_Alerts!$A:$A),"No Alert") | M1735: =IFERROR(XLOOKUP(A1735,Raw_Alerts!$B:$B,Raw_Alerts!$C:$C),"") | N1735: =IFERROR(XLOOKUP(A1735,Raw_Alerts!$B:$B,Raw_Alerts!$D:$D),"") | O1735: =IFERROR(XLOOKUP(A1735,Raw_Alerts!$B:$B,Raw_Alerts!$F:$F),"") | P1735: =IF(H1735="Not Found","CRITICAL: No Risk Profile",IF(I1735="Missing","WARN: Missing KYC",IF(I1735="Expired","WARN: KYC Expired",IF(I1735="Pending","INFO: KYC Pending","OK"))))

Sheet Weekly_MIS_Report
A1: Week # | B1: Week Start | C1: Week End | D1: Total Transactions | E1: Total Alerts | F1: Structuring Alerts | G1: Velocity Alerts | H1: High-Risk Country | I1: Round-Amount | J1: Dormant-Reactivation | K1: Open Alerts | L1: Escalated Alerts | M1: Closed Alerts | N1: Avg Resolution Days | O1: SLA Breach (>7d) | P1: Alert Rate %
A2: 1 | B2: 2026-01-01 | C2: 2026-01-07 | D2: =COUNTIFS(Raw_Transactions!$C:$C,">="&B2,Raw_Transactions!$C:$C,"<="&C2) | E2: =COUNTIFS(Raw_Alerts!$D:$D,">="&B2,Raw_Alerts!$D:$D,"<="&C2) | F2: =COUNTIFS(Raw_Alerts!$D:$D,">="&B2,Raw_Alerts!$D:$D,"<="&C2,Raw_Alerts!$C:$C,"Structuring") | G2: =COUNTIFS(Raw_Alerts!$D:$D,">="&B2,Raw_Alerts!$D:$D,"<="&C2,Raw_Alerts!$C:$C,"Velocity") | H2: =COUNTIFS(Raw_Alerts!$D:$D,">="&B2,Raw_Alerts!$D:$D,"<="&C2,Raw_Alerts!$C:$C,"High-Risk Country") | I2: =COUNTIFS(Raw_Alerts!$D:$D,">="&B2,Raw_Alerts!$D:$D,"<="&C2,Raw_Alerts!$C:$C,"Round-Amount") | J2: =COUNTIFS(Raw_Alerts!$D:$D,">="&B2,Raw_Alerts!$D:$D,"<="&C2,Raw_Alerts!$C:$C,"Dormant-Reactivation") | K2: =COUNTIFS(Raw_Alerts!$D:$D,">="&B2,Raw_Alerts!$D:$D,"<="&C2,Raw_Alerts!$E:$E,"Open") | L2: =COUNTIFS(Raw_Alerts!$D:$D,">="&B2,Raw_Alerts!$D:$D,"<="&C2,Raw_Alerts!$E:$E,"Escalated") | M2: =COUNTIFS(Raw_Alerts!$D:$D,">="&B2,Raw_Alerts!$D:$D,"<="&C2,Raw_Alerts!$E:$E,"Closed") | N2: =IFERROR(AVERAGEIFS(Raw_Alerts!$F:$F,Raw_Alerts!$D:$D,">="&B2,Raw_Alerts!$D:$D,"<="&C2,Raw_Alerts!$E:$E,"Closed"),0) | O2: =COUNTIFS(Raw_Alerts!$D:$D,">="&B2,Raw_Alerts!$D:$D,"<="&C2,Raw_Alerts!$F:$F,">"&7) | P2: =IFERROR(E2/D2,0)
A3: 2 | B3: 2026-01-08 | C3: 2026-01-14 | D3: =COUNTIFS(Raw_Transactions!$C:$C,">="&B3,Raw_Transactions!$C:$C,"<="&C3) | E3: =COUNTIFS(Raw_Alerts!$D:$D,">="&B3,Raw_Alerts!$D:$D,"<="&C3) | F3: =COUNTIFS(Raw_Alerts!$D:$D,">="&B3,Raw_Alerts!$D:$D,"<="&C3,Raw_Alerts!$C:$C,"Structuring") | G3: =COUNTIFS(Raw_Alerts!$D:$D,">="&B3,Raw_Alerts!$D:$D,"<="&C3,Raw_Alerts!$C:$C,"Velocity") | H3: =COUNTIFS(Raw_Alerts!$D:$D,">="&B3,Raw_Alerts!$D:$D,"<="&C3,Raw_Alerts!$C:$C,"High-Risk Country") | I3: =COUNTIFS(Raw_Alerts!$D:$D,">="&B3,Raw_Alerts!$D:$D,"<="&C3,Raw_Alerts!$C:$C,"Round-Amount") | J3: =COUNTIFS(Raw_Alerts!$D:$D,">="&B3,Raw_Alerts!$D:$D,"<="&C3,Raw_Alerts!$C:$C,"Dormant-Reactivation") | K3: =COUNTIFS(Raw_Alerts!$D:$D,">="&B3,Raw_Alerts!$D:$D,"<="&C3,Raw_Alerts!$E:$E,"Open") | L3: =COUNTIFS(Raw_Alerts!$D:$D,">="&B3,Raw_Alerts!$D:$D,"<="&C3,Raw_Alerts!$E:$E,"Escalated") | M3: =COUNTIFS(Raw_Alerts!$D:$D,">="&B3,Raw_Alerts!$D:$D,"<="&C3,Raw_Alerts!$E:$E,"Closed") | N3: =IFERROR(AVERAGEIFS(Raw_Alerts!$F:$F,Raw_Alerts!$D:$D,">="&B3,Raw_Alerts!$D:$D,"<="&C3,Raw_Alerts!$E:$E,"Closed"),0) | O3: =COUNTIFS(Raw_Alerts!$D:$D,">="&B3,Raw_Alerts!$D:$D,"<="&C3,Raw_Alerts!$F:$F,">"&7) | P3: =IFERROR(E3/D3,0)
A4: 3 | B4: 2026-01-15 | C4: 2026-01-21 | D4: =COUNTIFS(Raw_Transactions!$C:$C,">="&B4,Raw_Transactions!$C:$C,"<="&C4) | E4: =COUNTIFS(Raw_Alerts!$D:$D,">="&B4,Raw_Alerts!$D:$D,"<="&C4) | F4: =COUNTIFS(Raw_Alerts!$D:$D,">="&B4,Raw_Alerts!$D:$D,"<="&C4,Raw_Alerts!$C:$C,"Structuring") | G4: =COUNTIFS(Raw_Alerts!$D:$D,">="&B4,Raw_Alerts!$D:$D,"<="&C4,Raw_Alerts!$C:$C,"Velocity") | H4: =COUNTIFS(Raw_Alerts!$D:$D,">="&B4,Raw_Alerts!$D:$D,"<="&C4,Raw_Alerts!$C:$C,"High-Risk Country") | I4: =COUNTIFS(Raw_Alerts!$D:$D,">="&B4,Raw_Alerts!$D:$D,"<="&C4,Raw_Alerts!$C:$C,"Round-Amount") | J4: =COUNTIFS(Raw_Alerts!$D:$D,">="&B4,Raw_Alerts!$D:$D,"<="&C4,Raw_Alerts!$C:$C,"Dormant-Reactivation") | K4: =COUNTIFS(Raw_Alerts!$D:$D,">="&B4,Raw_Alerts!$D:$D,"<="&C4,Raw_Alerts!$E:$E,"Open") | L4: =COUNTIFS(Raw_Alerts!$D:$D,">="&B4,Raw_Alerts!$D:$D,"<="&C4,Raw_Alerts!$E:$E,"Escalated") | M4: =COUNTIFS(Raw_Alerts!$D:$D,">="&B4,Raw_Alerts!$D:$D,"<="&C4,Raw_Alerts!$E:$E,"Closed") | N4: =IFERROR(AVERAGEIFS(Raw_Alerts!$F:$F,Raw_Alerts!$D:$D,">="&B4,Raw_Alerts!$D:$D,"<="&C4,Raw_Alerts!$E:$E,"Closed"),0) | O4: =COUNTIFS(Raw_Alerts!$D:$D,">="&B4,Raw_Alerts!$D:$D,"<="&C4,Raw_Alerts!$F:$F,">"&7) | P4: =IFERROR(E4/D4,0)
A5: 4 | B5: 2026-01-22 | C5: 2026-01-28 | D5: =COUNTIFS(Raw_Transactions!$C:$C,">="&B5,Raw_Transactions!$C:$C,"<="&C5) | E5: =COUNTIFS(Raw_Alerts!$D:$D,">="&B5,Raw_Alerts!$D:$D,"<="&C5) | F5: =COUNTIFS(Raw_Alerts!$D:$D,">="&B5,Raw_Alerts!$D:$D,"<="&C5,Raw_Alerts!$C:$C,"Structuring") | G5: =COUNTIFS(Raw_Alerts!$D:$D,">="&B5,Raw_Alerts!$D:$D,"<="&C5,Raw_Alerts!$C:$C,"Velocity") | H5: =COUNTIFS(Raw_Alerts!$D:$D,">="&B5,Raw_Alerts!$D:$D,"<="&C5,Raw_Alerts!$C:$C,"High-Risk Country") | I5: =COUNTIFS(Raw_Alerts!$D:$D,">="&B5,Raw_Alerts!$D:$D,"<="&C5,Raw_Alerts!$C:$C,"Round-Amount") | J5: =COUNTIFS(Raw_Alerts!$D:$D,">="&B5,Raw_Alerts!$D:$D,"<="&C5,Raw_Alerts!$C:$C,"Dormant-Reactivation") | K5: =COUNTIFS(Raw_Alerts!$D:$D,">="&B5,Raw_Alerts!$D:$D,"<="&C5,Raw_Alerts!$E:$E,"Open") | L5: =COUNTIFS(Raw_Alerts!$D:$D,">="&B5,Raw_Alerts!$D:$D,"<="&C5,Raw_Alerts!$E:$E,"Escalated") | M5: =COUNTIFS(Raw_Alerts!$D:$D,">="&B5,Raw_Alerts!$D:$D,"<="&C5,Raw_Alerts!$E:$E,"Closed") | N5: =IFERROR(AVERAGEIFS(Raw_Alerts!$F:$F,Raw_Alerts!$D:$D,">="&B5,Raw_Alerts!$D:$D,"<="&C5,Raw_Alerts!$E:$E,"Closed"),0) | O5: =COUNTIFS(Raw_Alerts!$D:$D,">="&B5,Raw_Alerts!$D:$D,"<="&C5,Raw_Alerts!$F:$F,">"&7) | P5: =IFERROR(E5/D5,0)
A6: 5 | B6: 2026-01-29 | C6: 2026-02-04 | D6: =COUNTIFS(Raw_Transactions!$C:$C,">="&B6,Raw_Transactions!$C:$C,"<="&C6) | E6: =COUNTIFS(Raw_Alerts!$D:$D,">="&B6,Raw_Alerts!$D:$D,"<="&C6) | F6: =COUNTIFS(Raw_Alerts!$D:$D,">="&B6,Raw_Alerts!$D:$D,"<="&C6,Raw_Alerts!$C:$C,"Structuring") | G6: =COUNTIFS(Raw_Alerts!$D:$D,">="&B6,Raw_Alerts!$D:$D,"<="&C6,Raw_Alerts!$C:$C,"Velocity") | H6: =COUNTIFS(Raw_Alerts!$D:$D,">="&B6,Raw_Alerts!$D:$D,"<="&C6,Raw_Alerts!$C:$C,"High-Risk Country") | I6: =COUNTIFS(Raw_Alerts!$D:$D,">="&B6,Raw_Alerts!$D:$D,"<="&C6,Raw_Alerts!$C:$C,"Round-Amount") | J6: =COUNTIFS(Raw_Alerts!$D:$D,">="&B6,Raw_Alerts!$D:$D,"<="&C6,Raw_Alerts!$C:$C,"Dormant-Reactivation") | K6: =COUNTIFS(Raw_Alerts!$D:$D,">="&B6,Raw_Alerts!$D:$D,"<="&C6,Raw_Alerts!$E:$E,"Open") | L6: =COUNTIFS(Raw_Alerts!$D:$D,">="&B6,Raw_Alerts!$D:$D,"<="&C6,Raw_Alerts!$E:$E,"Escalated") | M6: =COUNTIFS(Raw_Alerts!$D:$D,">="&B6,Raw_Alerts!$D:$D,"<="&C6,Raw_Alerts!$E:$E,"Closed") | N6: =IFERROR(AVERAGEIFS(Raw_Alerts!$F:$F,Raw_Alerts!$D:$D,">="&B6,Raw_Alerts!$D:$D,"<="&C6,Raw_Alerts!$E:$E,"Closed"),0) | O6: =COUNTIFS(Raw_Alerts!$D:$D,">="&B6,Raw_Alerts!$D:$D,"<="&C6,Raw_Alerts!$F:$F,">"&7) | P6: =IFERROR(E6/D6,0)
A7: 6 | B7: 2026-02-05 | C7: 2026-02-11 | D7: =COUNTIFS(Raw_Transactions!$C:$C,">="&B7,Raw_Transactions!$C:$C,"<="&C7) | E7: =COUNTIFS(Raw_Alerts!$D:$D,">="&B7,Raw_Alerts!$D:$D,"<="&C7) | F7: =COUNTIFS(Raw_Alerts!$D:$D,">="&B7,Raw_Alerts!$D:$D,"<="&C7,Raw_Alerts!$C:$C,"Structuring") | G7: =COUNTIFS(Raw_Alerts!$D:$D,">="&B7,Raw_Alerts!$D:$D,"<="&C7,Raw_Alerts!$C:$C,"Velocity") | H7: =COUNTIFS(Raw_Alerts!$D:$D,">="&B7,Raw_Alerts!$D:$D,"<="&C7,Raw_Alerts!$C:$C,"High-Risk Country") | I7: =COUNTIFS(Raw_Alerts!$D:$D,">="&B7,Raw_Alerts!$D:$D,"<="&C7,Raw_Alerts!$C:$C,"Round-Amount") | J7: =COUNTIFS(Raw_Alerts!$D:$D,">="&B7,Raw_Alerts!$D:$D,"<="&C7,Raw_Alerts!$C:$C,"Dormant-Reactivation") | K7: =COUNTIFS(Raw_Alerts!$D:$D,">="&B7,Raw_Alerts!$D:$D,"<="&C7,Raw_Alerts!$E:$E,"Open") | L7: =COUNTIFS(Raw_Alerts!$D:$D,">="&B7,Raw_Alerts!$D:$D,"<="&C7,Raw_Alerts!$E:$E,"Escalated") | M7: =COUNTIFS(Raw_Alerts!$D:$D,">="&B7,Raw_Alerts!$D:$D,"<="&C7,Raw_Alerts!$E:$E,"Closed") | N7: =IFERROR(AVERAGEIFS(Raw_Alerts!$F:$F,Raw_Alerts!$D:$D,">="&B7,Raw_Alerts!$D:$D,"<="&C7,Raw_Alerts!$E:$E,"Closed"),0) | O7: =COUNTIFS(Raw_Alerts!$D:$D,">="&B7,Raw_Alerts!$D:$D,"<="&C7,Raw_Alerts!$F:$F,">"&7) | P7: =IFERROR(E7/D7,0)
A8: 7 | B8: 2026-02-12 | C8: 2026-02-18 | D8: =COUNTIFS(Raw_Transactions!$C:$C,">="&B8,Raw_Transactions!$C:$C,"<="&C8) | E8: =COUNTIFS(Raw_Alerts!$D:$D,">="&B8,Raw_Alerts!$D:$D,"<="&C8) | F8: =COUNTIFS(Raw_Alerts!$D:$D,">="&B8,Raw_Alerts!$D:$D,"<="&C8,Raw_Alerts!$C:$C,"Structuring") | G8: =COUNTIFS(Raw_Alerts!$D:$D,">="&B8,Raw_Alerts!$D:$D,"<="&C8,Raw_Alerts!$C:$C,"Velocity") | H8: =COUNTIFS(Raw_Alerts!$D:$D,">="&B8,Raw_Alerts!$D:$D,"<="&C8,Raw_Alerts!$C:$C,"High-Risk Country") | I8: =COUNTIFS(Raw_Alerts!$D:$D,">="&B8,Raw_Alerts!$D:$D,"<="&C8,Raw_Alerts!$C:$C,"Round-Amount") | J8: =COUNTIFS(Raw_Alerts!$D:$D,">="&B8,Raw_Alerts!$D:$D,"<="&C8,Raw_Alerts!$C:$C,"Dormant-Reactivation") | K8: =COUNTIFS(Raw_Alerts!$D:$D,">="&B8,Raw_Alerts!$D:$D,"<="&C8,Raw_Alerts!$E:$E,"Open") | L8: =COUNTIFS(Raw_Alerts!$D:$D,">="&B8,Raw_Alerts!$D:$D,"<="&C8,Raw_Alerts!$E:$E,"Escalated") | M8: =COUNTIFS(Raw_Alerts!$D:$D,">="&B8,Raw_Alerts!$D:$D,"<="&C8,Raw_Alerts!$E:$E,"Closed") | N8: =IFERROR(AVERAGEIFS(Raw_Alerts!$F:$F,Raw_Alerts!$D:$D,">="&B8,Raw_Alerts!$D:$D,"<="&C8,Raw_Alerts!$E:$E,"Closed"),0) | O8: =COUNTIFS(Raw_Alerts!$D:$D,">="&B8,Raw_Alerts!$D:$D,"<="&C8,Raw_Alerts!$F:$F,">"&7) | P8: =IFERROR(E8/D8,0)
A9: 8 | B9: 2026-02-19 | C9: 2026-02-25 | D9: =COUNTIFS(Raw_Transactions!$C:$C,">="&B9,Raw_Transactions!$C:$C,"<="&C9) | E9: =COUNTIFS(Raw_Alerts!$D:$D,">="&B9,Raw_Alerts!$D:$D,"<="&C9) | F9: =COUNTIFS(Raw_Alerts!$D:$D,">="&B9,Raw_Alerts!$D:$D,"<="&C9,Raw_Alerts!$C:$C,"Structuring") | G9: =COUNTIFS(Raw_Alerts!$D:$D,">="&B9,Raw_Alerts!$D:$D,"<="&C9,Raw_Alerts!$C:$C,"Velocity") | H9: =COUNTIFS(Raw_Alerts!$D:$D,">="&B9,Raw_Alerts!$D:$D,"<="&C9,Raw_Alerts!$C:$C,"High-Risk Country") | I9: =COUNTIFS(Raw_Alerts!$D:$D,">="&B9,Raw_Alerts!$D:$D,"<="&C9,Raw_Alerts!$C:$C,"Round-Amount") | J9: =COUNTIFS(Raw_Alerts!$D:$D,">="&B9,Raw_Alerts!$D:$D,"<="&C9,Raw_Alerts!$C:$C,"Dormant-Reactivation") | K9: =COUNTIFS(Raw_Alerts!$D:$D,">="&B9,Raw_Alerts!$D:$D,"<="&C9,Raw_Alerts!$E:$E,"Open") | L9: =COUNTIFS(Raw_Alerts!$D:$D,">="&B9,Raw_Alerts!$D:$D,"<="&C9,Raw_Alerts!$E:$E,"Escalated") | M9: =COUNTIFS(Raw_Alerts!$D:$D,">="&B9,Raw_Alerts!$D:$D,"<="&C9,Raw_Alerts!$E:$E,"Closed") | N9: =IFERROR(AVERAGEIFS(Raw_Alerts!$F:$F,Raw_Alerts!$D:$D,">="&B9,Raw_Alerts!$D:$D,"<="&C9,Raw_Alerts!$E:$E,"Closed"),0) | O9: =COUNTIFS(Raw_Alerts!$D:$D,">="&B9,Raw_Alerts!$D:$D,"<="&C9,Raw_Alerts!$F:$F,">"&7) | P9: =IFERROR(E9/D9,0)
A10: 9 | B10: 2026-02-26 | C10: 2026-03-04 | D10: =COUNTIFS(Raw_Transactions!$C:$C,">="&B10,Raw_Transactions!$C:$C,"<="&C10) | E10: =COUNTIFS(Raw_Alerts!$D:$D,">="&B10,Raw_Alerts!$D:$D,"<="&C10) | F10: =COUNTIFS(Raw_Alerts!$D:$D,">="&B10,Raw_Alerts!$D:$D,"<="&C10,Raw_Alerts!$C:$C,"Structuring") | G10: =COUNTIFS(Raw_Alerts!$D:$D,">="&B10,Raw_Alerts!$D:$D,"<="&C10,Raw_Alerts!$C:$C,"Velocity") | H10: =COUNTIFS(Raw_Alerts!$D:$D,">="&B10,Raw_Alerts!$D:$D,"<="&C10,Raw_Alerts!$C:$C,"High-Risk Country") | I10: =COUNTIFS(Raw_Alerts!$D:$D,">="&B10,Raw_Alerts!$D:$D,"<="&C10,Raw_Alerts!$C:$C,"Round-Amount") | J10: =COUNTIFS(Raw_Alerts!$D:$D,">="&B10,Raw_Alerts!$D:$D,"<="&C10,Raw_Alerts!$C:$C,"Dormant-Reactivation") | K10: =COUNTIFS(Raw_Alerts!$D:$D,">="&B10,Raw_Alerts!$D:$D,"<="&C10,Raw_Alerts!$E:$E,"Open") | L10: =COUNTIFS(Raw_Alerts!$D:$D,">="&B10,Raw_Alerts!$D:$D,"<="&C10,Raw_Alerts!$E:$E,"Escalated") | M10: =COUNTIFS(Raw_Alerts!$D:$D,">="&B10,Raw_Alerts!$D:$D,"<="&C10,Raw_Alerts!$E:$E,"Closed") | N10: =IFERROR(AVERAGEIFS(Raw_Alerts!$F:$F,Raw_Alerts!$D:$D,">="&B10,Raw_Alerts!$D:$D,"<="&C10,Raw_Alerts!$E:$E,"Closed"),0) | O10: =COUNTIFS(Raw_Alerts!$D:$D,">="&B10,Raw_Alerts!$D:$D,"<="&C10,Raw_Alerts!$F:$F,">"&7) | P10: =IFERROR(E10/D10,0)
A11: 10 | B11: 2026-03-05 | C11: 2026-03-11 | D11: =COUNTIFS(Raw_Transactions!$C:$C,">="&B11,Raw_Transactions!$C:$C,"<="&C11) | E11: =COUNTIFS(Raw_Alerts!$D:$D,">="&B11,Raw_Alerts!$D:$D,"<="&C11) | F11: =COUNTIFS(Raw_Alerts!$D:$D,">="&B11,Raw_Alerts!$D:$D,"<="&C11,Raw_Alerts!$C:$C,"Structuring") | G11: =COUNTIFS(Raw_Alerts!$D:$D,">="&B11,Raw_Alerts!$D:$D,"<="&C11,Raw_Alerts!$C:$C,"Velocity") | H11: =COUNTIFS(Raw_Alerts!$D:$D,">="&B11,Raw_Alerts!$D:$D,"<="&C11,Raw_Alerts!$C:$C,"High-Risk Country") | I11: =COUNTIFS(Raw_Alerts!$D:$D,">="&B11,Raw_Alerts!$D:$D,"<="&C11,Raw_Alerts!$C:$C,"Round-Amount") | J11: =COUNTIFS(Raw_Alerts!$D:$D,">="&B11,Raw_Alerts!$D:$D,"<="&C11,Raw_Alerts!$C:$C,"Dormant-Reactivation") | K11: =COUNTIFS(Raw_Alerts!$D:$D,">="&B11,Raw_Alerts!$D:$D,"<="&C11,Raw_Alerts!$E:$E,"Open") | L11: =COUNTIFS(Raw_Alerts!$D:$D,">="&B11,Raw_Alerts!$D:$D,"<="&C11,Raw_Alerts!$E:$E,"Escalated") | M11: =COUNTIFS(Raw_Alerts!$D:$D,">="&B11,Raw_Alerts!$D:$D,"<="&C11,Raw_Alerts!$E:$E,"Closed") | N11: =IFERROR(AVERAGEIFS(Raw_Alerts!$F:$F,Raw_Alerts!$D:$D,">="&B11,Raw_Alerts!$D:$D,"<="&C11,Raw_Alerts!$E:$E,"Closed"),0) | O11: =COUNTIFS(Raw_Alerts!$D:$D,">="&B11,Raw_Alerts!$D:$D,"<="&C11,Raw_Alerts!$F:$F,">"&7) | P11: =IFERROR(E11/D11,0)
A12: 11 | B12: 2026-03-12 | C12: 2026-03-18 | D12: =COUNTIFS(Raw_Transactions!$C:$C,">="&B12,Raw_Transactions!$C:$C,"<="&C12) | E12: =COUNTIFS(Raw_Alerts!$D:$D,">="&B12,Raw_Alerts!$D:$D,"<="&C12) | F12: =COUNTIFS(Raw_Alerts!$D:$D,">="&B12,Raw_Alerts!$D:$D,"<="&C12,Raw_Alerts!$C:$C,"Structuring") | G12: =COUNTIFS(Raw_Alerts!$D:$D,">="&B12,Raw_Alerts!$D:$D,"<="&C12,Raw_Alerts!$C:$C,"Velocity") | H12: =COUNTIFS(Raw_Alerts!$D:$D,">="&B12,Raw_Alerts!$D:$D,"<="&C12,Raw_Alerts!$C:$C,"High-Risk Country") | I12: =COUNTIFS(Raw_Alerts!$D:$D,">="&B12,Raw_Alerts!$D:$D,"<="&C12,Raw_Alerts!$C:$C,"Round-Amount") | J12: =COUNTIFS(Raw_Alerts!$D:$D,">="&B12,Raw_Alerts!$D:$D,"<="&C12,Raw_Alerts!$C:$C,"Dormant-Reactivation") | K12: =COUNTIFS(Raw_Alerts!$D:$D,">="&B12,Raw_Alerts!$D:$D,"<="&C12,Raw_Alerts!$E:$E,"Open") | L12: =COUNTIFS(Raw_Alerts!$D:$D,">="&B12,Raw_Alerts!$D:$D,"<="&C12,Raw_Alerts!$E:$E,"Escalated") | M12: =COUNTIFS(Raw_Alerts!$D:$D,">="&B12,Raw_Alerts!$D:$D,"<="&C12,Raw_Alerts!$E:$E,"Closed") | N12: =IFERROR(AVERAGEIFS(Raw_Alerts!$F:$F,Raw_Alerts!$D:$D,">="&B12,Raw_Alerts!$D:$D,"<="&C12,Raw_Alerts!$E:$E,"Closed"),0) | O12: =COUNTIFS(Raw_Alerts!$D:$D,">="&B12,Raw_Alerts!$D:$D,"<="&C12,Raw_Alerts!$F:$F,">"&7) | P12: =IFERROR(E12/D12,0)
A13: 12 | B13: 2026-03-19 | C13: 2026-03-25 | D13: =COUNTIFS(Raw_Transactions!$C:$C,">="&B13,Raw_Transactions!$C:$C,"<="&C13) | E13: =COUNTIFS(Raw_Alerts!$D:$D,">="&B13,Raw_Alerts!$D:$D,"<="&C13) | F13: =COUNTIFS(Raw_Alerts!$D:$D,">="&B13,Raw_Alerts!$D:$D,"<="&C13,Raw_Alerts!$C:$C,"Structuring") | G13: =COUNTIFS(Raw_Alerts!$D:$D,">="&B13,Raw_Alerts!$D:$D,"<="&C13,Raw_Alerts!$C:$C,"Velocity") | H13: =COUNTIFS(Raw_Alerts!$D:$D,">="&B13,Raw_Alerts!$D:$D,"<="&C13,Raw_Alerts!$C:$C,"High-Risk Country") | I13: =COUNTIFS(Raw_Alerts!$D:$D,">="&B13,Raw_Alerts!$D:$D,"<="&C13,Raw_Alerts!$C:$C,"Round-Amount") | J13: =COUNTIFS(Raw_Alerts!$D:$D,">="&B13,Raw_Alerts!$D:$D,"<="&C13,Raw_Alerts!$C:$C,"Dormant-Reactivation") | K13: =COUNTIFS(Raw_Alerts!$D:$D,">="&B13,Raw_Alerts!$D:$D,"<="&C13,Raw_Alerts!$E:$E,"Open") | L13: =COUNTIFS(Raw_Alerts!$D:$D,">="&B13,Raw_Alerts!$D:$D,"<="&C13,Raw_Alerts!$E:$E,"Escalated") | M13: =COUNTIFS(Raw_Alerts!$D:$D,">="&B13,Raw_Alerts!$D:$D,"<="&C13,Raw_Alerts!$E:$E,"Closed") | N13: =IFERROR(AVERAGEIFS(Raw_Alerts!$F:$F,Raw_Alerts!$D:$D,">="&B13,Raw_Alerts!$D:$D,"<="&C13,Raw_Alerts!$E:$E,"Closed"),0) | O13: =COUNTIFS(Raw_Alerts!$D:$D,">="&B13,Raw_Alerts!$D:$D,"<="&C13,Raw_Alerts!$F:$F,">"&7) | P13: =IFERROR(E13/D13,0)
... A19: 18 | B19: 2026-04-30 | C19: 2026-04-30 | D19: =COUNTIFS(Raw_Transactions!$C:$C,">="&B19,Raw_Transactions!$C:$C,"<="&C19) | E19: =COUNTIFS(Raw_Alerts!$D:$D,">="&B19,Raw_Alerts!$D:$D,"<="&C19) | F19: =COUNTIFS(Raw_Alerts!$D:$D,">="&B19,Raw_Alerts!$D:$D,"<="&C19,Raw_Alerts!$C:$C,"Structuring") | G19: =COUNTIFS(Raw_Alerts!$D:$D,">="&B19,Raw_Alerts!$D:$D,"<="&C19,Raw_Alerts!$C:$C,"Velocity") | H19: =COUNTIFS(Raw_Alerts!$D:$D,">="&B19,Raw_Alerts!$D:$D,"<="&C19,Raw_Alerts!$C:$C,"High-Risk Country") | I19: =COUNTIFS(Raw_Alerts!$D:$D,">="&B19,Raw_Alerts!$D:$D,"<="&C19,Raw_Alerts!$C:$C,"Round-Amount") | J19: =COUNTIFS(Raw_Alerts!$D:$D,">="&B19,Raw_Alerts!$D:$D,"<="&C19,Raw_Alerts!$C:$C,"Dormant-Reactivation") | K19: =COUNTIFS(Raw_Alerts!$D:$D,">="&B19,Raw_Alerts!$D:$D,"<="&C19,Raw_Alerts!$E:$E,"Open") | L19: =COUNTIFS(Raw_Alerts!$D:$D,">="&B19,Raw_Alerts!$D:$D,"<="&C19,Raw_Alerts!$E:$E,"Escalated") | M19: =COUNTIFS(Raw_Alerts!$D:$D,">="&B19,Raw_Alerts!$D:$D,"<="&C19,Raw_Alerts!$E:$E,"Closed") | N19: =IFERROR(AVERAGEIFS(Raw_Alerts!$F:$F,Raw_Alerts!$D:$D,">="&B19,Raw_Alerts!$D:$D,"<="&C19,Raw_Alerts!$E:$E,"Closed"),0) | O19: =COUNTIFS(Raw_Alerts!$D:$D,">="&B19,Raw_Alerts!$D:$D,"<="&C19,Raw_Alerts!$F:$F,">"&7) | P19: =IFERROR(E19/D19,0)

Sheet Monthly_MIS_Report
A1: Month | B1: Month Start | C1: Month End | D1: Total Transactions | E1: Total Alerts | F1: Structuring Alerts | G1: Velocity Alerts | H1: Open Alerts | I1: Escalated Alerts | J1: Closed Alerts | K1: Avg Resolution Days | L1: SLA Breach Count | M1: Alert Rate % | N1: MoM Alert Change | O1: MoM SLA Breach Change
A2: January 2026 | B2: 2026-01-01 | C2: 2026-01-31 | D2: =COUNTIFS(Raw_Transactions!$C:$C,">="&B2,Raw_Transactions!$C:$C,"<="&C2) | E2: =COUNTIFS(Raw_Alerts!$D:$D,">="&B2,Raw_Alerts!$D:$D,"<="&C2) | F2: =COUNTIFS(Raw_Alerts!$D:$D,">="&B2,Raw_Alerts!$D:$D,"<="&C2,Raw_Alerts!$C:$C,"Structuring") | G2: =COUNTIFS(Raw_Alerts!$D:$D,">="&B2,Raw_Alerts!$D:$D,"<="&C2,Raw_Alerts!$C:$C,"Velocity") | H2: =COUNTIFS(Raw_Alerts!$D:$D,">="&B2,Raw_Alerts!$D:$D,"<="&C2,Raw_Alerts!$E:$E,"Open") | I2: =COUNTIFS(Raw_Alerts!$D:$D,">="&B2,Raw_Alerts!$D:$D,"<="&C2,Raw_Alerts!$E:$E,"Escalated") | J2: =COUNTIFS(Raw_Alerts!$D:$D,">="&B2,Raw_Alerts!$D:$D,"<="&C2,Raw_Alerts!$E:$E,"Closed") | K2: =IFERROR(AVERAGEIFS(Raw_Alerts!$F:$F,Raw_Alerts!$D:$D,">="&B2,Raw_Alerts!$D:$D,"<="&C2,Raw_Alerts!$E:$E,"Closed"),0) | L2: =COUNTIFS(Raw_Alerts!$D:$D,">="&B2,Raw_Alerts!$D:$D,"<="&C2,Raw_Alerts!$F:$F,">"&7) | M2: =IFERROR(E2/D2,0) | N2: N/A | O2: N/A
A3: February 2026 | B3: 2026-02-01 | C3: 2026-02-28 | D3: =COUNTIFS(Raw_Transactions!$C:$C,">="&B3,Raw_Transactions!$C:$C,"<="&C3) | E3: =COUNTIFS(Raw_Alerts!$D:$D,">="&B3,Raw_Alerts!$D:$D,"<="&C3) | F3: =COUNTIFS(Raw_Alerts!$D:$D,">="&B3,Raw_Alerts!$D:$D,"<="&C3,Raw_Alerts!$C:$C,"Structuring") | G3: =COUNTIFS(Raw_Alerts!$D:$D,">="&B3,Raw_Alerts!$D:$D,"<="&C3,Raw_Alerts!$C:$C,"Velocity") | H3: =COUNTIFS(Raw_Alerts!$D:$D,">="&B3,Raw_Alerts!$D:$D,"<="&C3,Raw_Alerts!$E:$E,"Open") | I3: =COUNTIFS(Raw_Alerts!$D:$D,">="&B3,Raw_Alerts!$D:$D,"<="&C3,Raw_Alerts!$E:$E,"Escalated") | J3: =COUNTIFS(Raw_Alerts!$D:$D,">="&B3,Raw_Alerts!$D:$D,"<="&C3,Raw_Alerts!$E:$E,"Closed") | K3: =IFERROR(AVERAGEIFS(Raw_Alerts!$F:$F,Raw_Alerts!$D:$D,">="&B3,Raw_Alerts!$D:$D,"<="&C3,Raw_Alerts!$E:$E,"Closed"),0) | L3: =COUNTIFS(Raw_Alerts!$D:$D,">="&B3,Raw_Alerts!$D:$D,"<="&C3,Raw_Alerts!$F:$F,">"&7) | M3: =IFERROR(E3/D3,0) | N3: =IFERROR((E3-E2)/E2,0) | O3: =IFERROR((L3-L2)/L2,0)
A4: March 2026 | B4: 2026-03-01 | C4: 2026-03-31 | D4: =COUNTIFS(Raw_Transactions!$C:$C,">="&B4,Raw_Transactions!$C:$C,"<="&C4) | E4: =COUNTIFS(Raw_Alerts!$D:$D,">="&B4,Raw_Alerts!$D:$D,"<="&C4) | F4: =COUNTIFS(Raw_Alerts!$D:$D,">="&B4,Raw_Alerts!$D:$D,"<="&C4,Raw_Alerts!$C:$C,"Structuring") | G4: =COUNTIFS(Raw_Alerts!$D:$D,">="&B4,Raw_Alerts!$D:$D,"<="&C4,Raw_Alerts!$C:$C,"Velocity") | H4: =COUNTIFS(Raw_Alerts!$D:$D,">="&B4,Raw_Alerts!$D:$D,"<="&C4,Raw_Alerts!$E:$E,"Open") | I4: =COUNTIFS(Raw_Alerts!$D:$D,">="&B4,Raw_Alerts!$D:$D,"<="&C4,Raw_Alerts!$E:$E,"Escalated") | J4: =COUNTIFS(Raw_Alerts!$D:$D,">="&B4,Raw_Alerts!$D:$D,"<="&C4,Raw_Alerts!$E:$E,"Closed") | K4: =IFERROR(AVERAGEIFS(Raw_Alerts!$F:$F,Raw_Alerts!$D:$D,">="&B4,Raw_Alerts!$D:$D,"<="&C4,Raw_Alerts!$E:$E,"Closed"),0) | L4: =COUNTIFS(Raw_Alerts!$D:$D,">="&B4,Raw_Alerts!$D:$D,"<="&C4,Raw_Alerts!$F:$F,">"&7) | M4: =IFERROR(E4/D4,0) | N4: =IFERROR((E4-E3)/E3,0) | O4: =IFERROR((L4-L3)/L3,0)
A5: April 2026 | B5: 2026-04-01 | C5: 2026-04-30 | D5: =COUNTIFS(Raw_Transactions!$C:$C,">="&B5,Raw_Transactions!$C:$C,"<="&C5) | E5: =COUNTIFS(Raw_Alerts!$D:$D,">="&B5,Raw_Alerts!$D:$D,"<="&C5) | F5: =COUNTIFS(Raw_Alerts!$D:$D,">="&B5,Raw_Alerts!$D:$D,"<="&C5,Raw_Alerts!$C:$C,"Structuring") | G5: =COUNTIFS(Raw_Alerts!$D:$D,">="&B5,Raw_Alerts!$D:$D,"<="&C5,Raw_Alerts!$C:$C,"Velocity") | H5: =COUNTIFS(Raw_Alerts!$D:$D,">="&B5,Raw_Alerts!$D:$D,"<="&C5,Raw_Alerts!$E:$E,"Open") | I5: =COUNTIFS(Raw_Alerts!$D:$D,">="&B5,Raw_Alerts!$D:$D,"<="&C5,Raw_Alerts!$E:$E,"Escalated") | J5: =COUNTIFS(Raw_Alerts!$D:$D,">="&B5,Raw_Alerts!$D:$D,"<="&C5,Raw_Alerts!$E:$E,"Closed") | K5: =IFERROR(AVERAGEIFS(Raw_Alerts!$F:$F,Raw_Alerts!$D:$D,">="&B5,Raw_Alerts!$D:$D,"<="&C5,Raw_Alerts!$E:$E,"Closed"),0) | L5: =COUNTIFS(Raw_Alerts!$D:$D,">="&B5,Raw_Alerts!$D:$D,"<="&C5,Raw_Alerts!$F:$F,">"&7) | M5: =IFERROR(E5/D5,0) | N5: =IFERROR((E5-E4)/E4,0) | O5: =IFERROR((L5-L4)/L4,0)

Sheet Ad_Hoc_Scorecard
A1: AML Alert Scorecard — Filter by Alert Type
A3: Select Alert Type: | B3: All
A5: Metric | B5: Q1 (Jan) | C5: Q2 Feb | D5: Q3 Mar | E5: Q4 Apr | F5: Total
A6: Alert Count | B6: =IF($B$3="All",COUNTIFS(Raw_Alerts!$D:$D,">="&"2026-01-01",Raw_Alerts!$D:$D,"<="&"2026-01-31"),COUNTIFS(Raw_Alerts!$C:$C,$B$3,Raw_Alerts!$D:$D,">="&"2026-01-01",Raw_Alerts!$D:$D,"<="&"2026-01-31")) | C6: =IF($B$3="All",COUNTIFS(Raw_Alerts!$D:$D,">="&"2026-02-01",Raw_Alerts!$D:$D,"<="&"2026-02-28"),COUNTIFS(Raw_Alerts!$C:$C,$B$3,Raw_Alerts!$D:$D,">="&"2026-02-01",Raw_Alerts!$D:$D,"<="&"2026-02-28")) | D6: =IF($B$3="All",COUNTIFS(Raw_Alerts!$D:$D,">="&"2026-03-01",Raw_Alerts!$D:$D,"<="&"2026-03-31"),COUNTIFS(Raw_Alerts!$C:$C,$B$3,Raw_Alerts!$D:$D,">="&"2026-03-01",Raw_Alerts!$D:$D,"<="&"2026-03-31")) | E6: =IF($B$3="All",COUNTIFS(Raw_Alerts!$D:$D,">="&"2026-04-01",Raw_Alerts!$D:$D,"<="&"2026-04-30"),COUNTIFS(Raw_Alerts!$C:$C,$B$3,Raw_Alerts!$D:$D,">="&"2026-04-01",Raw_Alerts!$D:$D,"<="&"2026-04-30")) | F6: =SUM(B6:E6)
A7: Open Alerts | B7: =IF($B$3="All",COUNTIFS(Raw_Alerts!$E:$E,"Open",Raw_Alerts!$D:$D,">="&"2026-01-01",Raw_Alerts!$D:$D,"<="&"2026-01-31"),COUNTIFS(Raw_Alerts!$C:$C,$B$3,Raw_Alerts!$E:$E,"Open",Raw_Alerts!$D:$D,">="&"2026-01-01",Raw_Alerts!$D:$D,"<="&"2026-01-31")) | C7: =IF($B$3="All",COUNTIFS(Raw_Alerts!$E:$E,"Open",Raw_Alerts!$D:$D,">="&"2026-02-01",Raw_Alerts!$D:$D,"<="&"2026-02-28"),COUNTIFS(Raw_Alerts!$C:$C,$B$3,Raw_Alerts!$E:$E,"Open",Raw_Alerts!$D:$D,">="&"2026-02-01",Raw_Alerts!$D:$D,"<="&"2026-02-28")) | D7: =IF($B$3="All",COUNTIFS(Raw_Alerts!$E:$E,"Open",Raw_Alerts!$D:$D,">="&"2026-03-01",Raw_Alerts!$D:$D,"<="&"2026-03-31"),COUNTIFS(Raw_Alerts!$C:$C,$B$3,Raw_Alerts!$E:$E,"Open",Raw_Alerts!$D:$D,">="&"2026-03-01",Raw_Alerts!$D:$D,"<="&"2026-03-31")) | E7: =IF($B$3="All",COUNTIFS(Raw_Alerts!$E:$E,"Open",Raw_Alerts!$D:$D,">="&"2026-04-01",Raw_Alerts!$D:$D,"<="&"2026-04-30"),COUNTIFS(Raw_Alerts!$C:$C,$B$3,Raw_Alerts!$E:$E,"Open",Raw_Alerts!$D:$D,">="&"2026-04-01",Raw_Alerts!$D:$D,"<="&"2026-04-30")) | F7: =SUM(B7:E7)
A8: Escalated Alerts | B8: =IF($B$3="All",COUNTIFS(Raw_Alerts!$E:$E,"Escalated",Raw_Alerts!$D:$D,">="&"2026-01-01",Raw_Alerts!$D:$D,"<="&"2026-01-31"),COUNTIFS(Raw_Alerts!$C:$C,$B$3,Raw_Alerts!$E:$E,"Escalated",Raw_Alerts!$D:$D,">="&"2026-01-01",Raw_Alerts!$D:$D,"<="&"2026-01-31")) | C8: =IF($B$3="All",COUNTIFS(Raw_Alerts!$E:$E,"Escalated",Raw_Alerts!$D:$D,">="&"2026-02-01",Raw_Alerts!$D:$D,"<="&"2026-02-28"),COUNTIFS(Raw_Alerts!$C:$C,$B$3,Raw_Alerts!$E:$E,"Escalated",Raw_Alerts!$D:$D,">="&"2026-02-01",Raw_Alerts!$D:$D,"<="&"2026-02-28")) | D8: =IF($B$3="All",COUNTIFS(Raw_Alerts!$E:$E,"Escalated",Raw_Alerts!$D:$D,">="&"2026-03-01",Raw_Alerts!$D:$D,"<="&"2026-03-31"),COUNTIFS(Raw_Alerts!$C:$C,$B$3,Raw_Alerts!$E:$E,"Escalated",Raw_Alerts!$D:$D,">="&"2026-03-01",Raw_Alerts!$D:$D,"<="&"2026-03-31")) | E8: =IF($B$3="All",COUNTIFS(Raw_Alerts!$E:$E,"Escalated",Raw_Alerts!$D:$D,">="&"2026-04-01",Raw_Alerts!$D:$D,"<="&"2026-04-30"),COUNTIFS(Raw_Alerts!$C:$C,$B$3,Raw_Alerts!$E:$E,"Escalated",Raw_Alerts!$D:$D,">="&"2026-04-01",Raw_Alerts!$D:$D,"<="&"2026-04-30")) | F8: =SUM(B8:E8)
A9: Closed Alerts | B9: =IF($B$3="All",COUNTIFS(Raw_Alerts!$E:$E,"Closed",Raw_Alerts!$D:$D,">="&"2026-01-01",Raw_Alerts!$D:$D,"<="&"2026-01-31"),COUNTIFS(Raw_Alerts!$C:$C,$B$3,Raw_Alerts!$E:$E,"Closed",Raw_Alerts!$D:$D,">="&"2026-01-01",Raw_Alerts!$D:$D,"<="&"2026-01-31")) | C9: =IF($B$3="All",COUNTIFS(Raw_Alerts!$E:$E,"Closed",Raw_Alerts!$D:$D,">="&"2026-02-01",Raw_Alerts!$D:$D,"<="&"2026-02-28"),COUNTIFS(Raw_Alerts!$C:$C,$B$3,Raw_Alerts!$E:$E,"Closed",Raw_Alerts!$D:$D,">="&"2026-02-01",Raw_Alerts!$D:$D,"<="&"2026-02-28")) | D9: =IF($B$3="All",COUNTIFS(Raw_Alerts!$E:$E,"Closed",Raw_Alerts!$D:$D,">="&"2026-03-01",Raw_Alerts!$D:$D,"<="&"2026-03-31"),COUNTIFS(Raw_Alerts!$C:$C,$B$3,Raw_Alerts!$E:$E,"Closed",Raw_Alerts!$D:$D,">="&"2026-03-01",Raw_Alerts!$D:$D,"<="&"2026-03-31")) | E9: =IF($B$3="All",COUNTIFS(Raw_Alerts!$E:$E,"Closed",Raw_Alerts!$D:$D,">="&"2026-04-01",Raw_Alerts!$D:$D,"<="&"2026-04-30"),COUNTIFS(Raw_Alerts!$C:$C,$B$3,Raw_Alerts!$E:$E,"Closed",Raw_Alerts!$D:$D,">="&"2026-04-01",Raw_Alerts!$D:$D,"<="&"2026-04-30")) | F9: =SUM(B9:E9)
A10: SLA Breaches (>7d) | B10: =IF($B$3="All",COUNTIFS(Raw_Alerts!$F:$F,">"&7,Raw_Alerts!$D:$D,">="&"2026-01-01",Raw_Alerts!$D:$D,"<="&"2026-01-31"),COUNTIFS(Raw_Alerts!$C:$C,$B$3,Raw_Alerts!$F:$F,">"&7,Raw_Alerts!$D:$D,">="&"2026-01-01",Raw_Alerts!$D:$D,"<="&"2026-01-31")) | C10: =IF($B$3="All",COUNTIFS(Raw_Alerts!$F:$F,">"&7,Raw_Alerts!$D:$D,">="&"2026-02-01",Raw_Alerts!$D:$D,"<="&"2026-02-28"),COUNTIFS(Raw_Alerts!$C:$C,$B$3,Raw_Alerts!$F:$F,">"&7,Raw_Alerts!$D:$D,">="&"2026-02-01",Raw_Alerts!$D:$D,"<="&"2026-02-28")) | D10: =IF($B$3="All",COUNTIFS(Raw_Alerts!$F:$F,">"&7,Raw_Alerts!$D:$D,">="&"2026-03-01",Raw_Alerts!$D:$D,"<="&"2026-03-31"),COUNTIFS(Raw_Alerts!$C:$C,$B$3,Raw_Alerts!$F:$F,">"&7,Raw_Alerts!$D:$D,">="&"2026-03-01",Raw_Alerts!$D:$D,"<="&"2026-03-31")) | E10: =IF($B$3="All",COUNTIFS(Raw_Alerts!$F:$F,">"&7,Raw_Alerts!$D:$D,">="&"2026-04-01",Raw_Alerts!$D:$D,"<="&"2026-04-30"),COUNTIFS(Raw_Alerts!$C:$C,$B$3,Raw_Alerts!$F:$F,">"&7,Raw_Alerts!$D:$D,">="&"2026-04-01",Raw_Alerts!$D:$D,"<="&"2026-04-30")) | F10: =SUM(B10:E10)

Sheet Dashboard
A1: AML TRANSACTION MONITORING MIS DASHBOARD | Jan-Apr 2026
A2: American Express — AML Compliance | Reporting Period: Q1 2026 (120 days)
A4: TOTAL TRANSACTIONS | D4: TOTAL ALERTS | G4: OPEN / ESCALATED | J4: STRUCTURING ALERTS | M4: HIGH-RISK CUSTOMERS
A5: =COUNTA(Raw_Transactions!$A:$A)-1 | D5: =COUNTA(Raw_Alerts!$A:$A)-1 | G5: =COUNTIF(Raw_Alerts!$E:$E,"Open")+COUNTIF(Raw_Alerts!$E:$E,"Escalated") | J5: =COUNTIF(Raw_Alerts!$C:$C,"Structuring") | M5: =COUNTIF(Raw_Risk_Profiles!$B:$B,"High")
A8: Weekly Alert Trend (Structuring Highlighted) | H8: Monthly MIS Summary
A9: Month | B9: Txns | C9: Alerts | D9: Struct | E9: SLA Breach | F9: Alert% | G9: MoM % | H9: Month | I9: Txns | J9: Alerts | K9: Struct | L9: SLA Breach | M9: Alert% | N9: MoM %
A10: =Weekly_MIS_Report!A2 | B10: =Weekly_MIS_Report!B2 | C10: =Weekly_MIS_Report!E2 | D10: =Weekly_MIS_Report!F2 | E10: =Weekly_MIS_Report!G2 | F10: =Weekly_MIS_Report!K2+Weekly_MIS_Report!L2 | H10: =Monthly_MIS_Report!A2 | I10: =Monthly_MIS_Report!D2 | J10: =Monthly_MIS_Report!E2 | K10: =Monthly_MIS_Report!F2 | L10: =Monthly_MIS_Report!L2 | M10: =Monthly_MIS_Report!M2 | N10: N/A
A11: =Weekly_MIS_Report!A3 | B11: =Weekly_MIS_Report!B3 | C11: =Weekly_MIS_Report!E3 | D11: =Weekly_MIS_Report!F3 | E11: =Weekly_MIS_Report!G3 | F11: =Weekly_MIS_Report!K3+Weekly_MIS_Report!L3 | H11: =Monthly_MIS_Report!A3 | I11: =Monthly_MIS_Report!D3 | J11: =Monthly_MIS_Report!E3 | K11: =Monthly_MIS_Report!F3 | L11: =Monthly_MIS_Report!L3 | M11: =Monthly_MIS_Report!M3 | N11: =Monthly_MIS_Report!N3
A12: =Weekly_MIS_Report!A4 | B12: =Weekly_MIS_Report!B4 | C12: =Weekly_MIS_Report!E4 | D12: =Weekly_MIS_Report!F4 | E12: =Weekly_MIS_Report!G4 | F12: =Weekly_MIS_Report!K4+Weekly_MIS_Report!L4 | H12: =Monthly_MIS_Report!A4 | I12: =Monthly_MIS_Report!D4 | J12: =Monthly_MIS_Report!E4 | K12: =Monthly_MIS_Report!F4 | L12: =Monthly_MIS_Report!L4 | M12: =Monthly_MIS_Report!M4 | N12: =Monthly_MIS_Report!N4
A13: =Weekly_MIS_Report!A5 | B13: =Weekly_MIS_Report!B5 | C13: =Weekly_MIS_Report!E5 | D13: =Weekly_MIS_Report!F5 | E13: =Weekly_MIS_Report!G5 | F13: =Weekly_MIS_Report!K5+Weekly_MIS_Report!L5 | H13: =Monthly_MIS_Report!A5 | I13: =Monthly_MIS_Report!D5 | J13: =Monthly_MIS_Report!E5 | K13: =Monthly_MIS_Report!F5 | L13: =Monthly_MIS_Report!L5 | M13: =Monthly_MIS_Report!M5 | N13: =Monthly_MIS_Report!N5
A14: =Weekly_MIS_Report!A6 | B14: =Weekly_MIS_Report!B6 | C14: =Weekly_MIS_Report!E6 | D14: =Weekly_MIS_Report!F6 | E14: =Weekly_MIS_Report!G6 | F14: =Weekly_MIS_Report!K6+Weekly_MIS_Report!L6
A15: =Weekly_MIS_Report!A7 | B15: =Weekly_MIS_Report!B7 | C15: =Weekly_MIS_Report!E7 | D15: =Weekly_MIS_Report!F7 | E15: =Weekly_MIS_Report!G7 | F15: =Weekly_MIS_Report!K7+Weekly_MIS_Report!L7
A16: =Weekly_MIS_Report!A8 | B16: =Weekly_MIS_Report!B8 | C16: =Weekly_MIS_Report!E8 | D16: =Weekly_MIS_Report!F8 | E16: =Weekly_MIS_Report!G8 | F16: =Weekly_MIS_Report!K8+Weekly_MIS_Report!L8
A17: =Weekly_MIS_Report!A9 | B17: =Weekly_MIS_Report!B9 | C17: =Weekly_MIS_Report!E9 | D17: =Weekly_MIS_Report!F9 | E17: =Weekly_MIS_Report!G9 | F17: =Weekly_MIS_Report!K9+Weekly_MIS_Report!L9
A18: =Weekly_MIS_Report!A10 | B18: =Weekly_MIS_Report!B10 | C18: =Weekly_MIS_Report!E10 | D18: =Weekly_MIS_Report!F10 | E18: =Weekly_MIS_Report!G10 | F18: =Weekly_MIS_Report!K10+Weekly_MIS_Report!L10
A19: =Weekly_MIS_Report!A11 | B19: =Weekly_MIS_Report!B11 | C19: =Weekly_MIS_Report!E11 | D19: =Weekly_MIS_Report!F11 | E19: =Weekly_MIS_Report!G11 | F19: =Weekly_MIS_Report!K11+Weekly_MIS_Report!L11
A20: =Weekly_MIS_Report!A12 | B20: =Weekly_MIS_Report!B12 | C20: =Weekly_MIS_Report!E12 | D20: =Weekly_MIS_Report!F12 | E20: =Weekly_MIS_Report!G12 | F20: =Weekly_MIS_Report!K12+Weekly_MIS_Report!L12
A21: =Weekly_MIS_Report!A13 | B21: =Weekly_MIS_Report!B13 | C21: =Weekly_MIS_Report!E13 | D21: =Weekly_MIS_Report!F13 | E21: =Weekly_MIS_Report!G13 | F21: =Weekly_MIS_Report!K13+Weekly_MIS_Report!L13
A22: =Weekly_MIS_Report!A14 | B22: =Weekly_MIS_Report!B14 | C22: =Weekly_MIS_Report!E14 | D22: =Weekly_MIS_Report!F14 | E22: =Weekly_MIS_Report!G14 | F22: =Weekly_MIS_Report!K14+Weekly_MIS_Report!L14
A23: =Weekly_MIS_Report!A15 | B23: =Weekly_MIS_Report!B15 | C23: =Weekly_MIS_Report!E15 | D23: =Weekly_MIS_Report!F15 | E23: =Weekly_MIS_Report!G15 | F23: =Weekly_MIS_Report!K15+Weekly_MIS_Report!L15
A24: =Weekly_MIS_Report!A16 | B24: =Weekly_MIS_Report!B16 | C24: =Weekly_MIS_Report!E16 | D24: =Weekly_MIS_Report!F16 | E24: =Weekly_MIS_Report!G16 | F24: =Weekly_MIS_Report!K16+Weekly_MIS_Report!L16
A25: =Weekly_MIS_Report!A17 | B25: =Weekly_MIS_Report!B17 | C25: =Weekly_MIS_Report!E17 | D25: =Weekly_MIS_Report!F17 | E25: =Weekly_MIS_Report!G17 | F25: =Weekly_MIS_Report!K17+Weekly_MIS_Report!L17
... A27: =Weekly_MIS_Report!A19 | B27: =Weekly_MIS_Report!B19 | C27: =Weekly_MIS_Report!E19 | D27: =Weekly_MIS_Report!F19 | E27: =Weekly_MIS_Report!G19 | F27: =Weekly_MIS_Report!K19+Weekly_MIS_Report!L19
A30: Data Quality Flag Summary
A31: Flag Type | B31: Count
A32: CRITICAL: No Risk Profile | B32: =COUNTIF(Consolidated_View!$P:$P,"CRITICAL*")
A33: WARN: Missing KYC | B33: =COUNTIF(Consolidated_View!$P:$P,"WARN: Missing KYC")
A34: WARN: KYC Expired | B34: =COUNTIF(Consolidated_View!$P:$P,"WARN: KYC Expired")
A35: INFO: KYC Pending | B35: =COUNTIF(Consolidated_View!$P:$P,"INFO*")
A36: OK — No Issues | B36: =COUNTIF(Consolidated_View!$P:$P,"OK")
